try {
    console.log(c+d);
} catch(err) {
    console.log("There was an Error");
    console.log("The Error was saved in the Error log");
}
console.log("This line now runs");